<?xml version="1.0" encoding="utf-8"?>
<robot name="Player">
  <material name="MetalBlack">
    <color rgba="0.2 0.2 0.2 1" />
  </material>
  <material name="Rubber">
    <color rgba="0.1 0.1 0.1 1" />
  </material>
  <link name="base_link">
    <inertial>
      <origin rpy="0 0 0" xyz="0 0 0" />
      <mass value="10" />
      <inertia ixx="1" ixy="0" ixz="0" iyy="1" iyz="0" izz="1" />
    </inertial>
    <visual>
      <origin rpy="-3.141593 0 0" />
      <geometry>
        <mesh filename="package://meshes/A4WD3-NWheeledMesh.stl" scale="1 1 1" />
      </geometry>
      <material name="MetalBlack" />
    </visual>
    <collision>
      <origin rpy="-3.141593 0 0" />
      <geometry>
        <mesh filename="package://meshes/A4WD3-NWheeledMesh.stl" scale="1 1 1" />
      </geometry>
    </collision>
  </link>
  <link name="FrontRight">
    <inertial>
      <origin rpy="0 0 0" xyz="0 0 0" />
      <mass value="0.5" />
      <inertia ixx="1" ixy="0" ixz="0" iyy="1" iyz="0" izz="1" />
    </inertial>
    <visual>
      <origin xyz="-0.1345 -0.11 0.035" />
      <geometry>
        <mesh filename="package://meshes/A4WD3-Wheel.stl" scale="1 1 1" />
      </geometry>
      <material name="Rubber" />
    </visual>
    <collision>
      <origin xyz="-0.1345 -0.11 0.035" />
      <geometry>
        <mesh filename="package://meshes/A4WD3-Wheel.stl" scale="1 1 1" />
      </geometry>
    </collision>
  </link>
  <link name="FrontLeft">
    <inertial>
      <origin rpy="0 0 0" xyz="0 0 0" />
      <mass value="0.5" />
      <inertia ixx="1" ixy="0" ixz="0" iyy="1" iyz="0" izz="1" />
    </inertial>
    <visual>
      <origin rpy="0 0 -3.141593" xyz="0.1345 -0.11 0.035" />
      <geometry>
        <mesh filename="package://meshes/A4WD3-Wheel.stl" scale="1 1 1" />
      </geometry>
      <material name="Rubber" />
    </visual>
    <collision>
      <origin rpy="0 0 -3.141593" xyz="0.1345 -0.11 0.035" />
      <geometry>
        <mesh filename="package://meshes/A4WD3-Wheel.stl" scale="1 1 1" />
      </geometry>
    </collision>
  </link>
  <link name="BackRight">
    <inertial>
      <origin rpy="0 0 0" xyz="0 0 0" />
      <mass value="0.5" />
      <inertia ixx="1" ixy="0" ixz="0" iyy="1" iyz="0" izz="1" />
    </inertial>
    <visual>
      <origin xyz="-0.1345 0.11 0.035" />
      <geometry>
        <mesh filename="package://meshes/A4WD3-Wheel.stl" scale="1 1 1" />
      </geometry>
      <material name="Rubber" />
    </visual>
    <collision>
      <origin xyz="-0.1345 0.11 0.035" />
      <geometry>
        <mesh filename="package://meshes/A4WD3-Wheel.stl" scale="1 1 1" />
      </geometry>
    </collision>
  </link>
  <link name="BackLeft">
    <inertial>
      <origin rpy="0 0 0" xyz="0 0 0" />
      <mass value="0.5" />
      <inertia ixx="1" ixy="0" ixz="0" iyy="1" iyz="0" izz="1" />
    </inertial>
    <visual>
      <origin rpy="0 0 -3.141593" xyz="0.1345 0.11 0.035" />
      <geometry>
        <mesh filename="package://meshes/A4WD3-Wheel.stl" scale="1 1 1" />
      </geometry>
      <material name="Rubber" />
    </visual>
    <collision>
      <origin rpy="0 0 -3.141593" xyz="0.1345 0.11 0.035" />
      <geometry>
        <mesh filename="package://meshes/A4WD3-Wheel.stl" scale="1 1 1" />
      </geometry>
    </collision>
  </link>
  <joint name="base_link_FrontRight_joint" type="continuous">
    <parent link="base_link" />
    <child link="FrontRight" />
    <axis xyz="1 0 0" />
  </joint>
  <joint name="base_link_FrontLeft_joint" type="continuous">
    <parent link="base_link" />
    <child link="FrontLeft" />
    <axis xyz="1 0 0" />
  </joint>
  <joint name="base_link_BackRight_joint" type="continuous">
    <parent link="base_link" />
    <child link="BackRight" />
    <axis xyz="1 0 0" />
  </joint>
  <joint name="base_link_BackLeft_joint" type="continuous">
    <parent link="base_link" />
    <child link="BackLeft" />
    <axis xyz="1 0 0" />
  </joint>
</robot>